  main_task.cpp
C:\work\cpp_python\git\nm_lab_1\dll_for_py\dll_for_py\main_task.cpp(47,7): error C2039: "vector": не является членом "std".
C:\work\cpp_python\git\nm_lab_1\dll_for_py\dll_for_py\predefined C++ types (compiler internal)(341): message : см. объявление "std"
C:\work\cpp_python\git\nm_lab_1\dll_for_py\dll_for_py\main_task.cpp(47,13): error C2065: vector: необъявленный идентификатор
C:\work\cpp_python\git\nm_lab_1\dll_for_py\dll_for_py\main_task.cpp(47,14): error C2062: тип "double" не требуется
C:\work\cpp_python\git\nm_lab_1\dll_for_py\dll_for_py\main_task.cpp(49,2): error C2065: d_v: необъявленный идентификатор
C:\work\cpp_python\git\nm_lab_1\dll_for_py\dll_for_py\main_task.cpp(50,2): error C2065: d_v: необъявленный идентификатор
C:\work\cpp_python\git\nm_lab_1\dll_for_py\dll_for_py\main_task.cpp(51,2): error C2065: d_v: необъявленный идентификатор
C:\work\cpp_python\git\nm_lab_1\dll_for_py\dll_for_py\main_task.cpp(52,2): error C2065: d_v: необъявленный идентификатор
C:\work\cpp_python\git\nm_lab_1\dll_for_py\dll_for_py\main_task.cpp(53,2): error C2065: d_v: необъявленный идентификатор
C:\work\cpp_python\git\nm_lab_1\dll_for_py\dll_for_py\main_task.cpp(54,2): error C2065: d_v: необъявленный идентификатор
C:\work\cpp_python\git\nm_lab_1\dll_for_py\dll_for_py\main_task.cpp(55,2): error C2065: d_v: необъявленный идентификатор
C:\work\cpp_python\git\nm_lab_1\dll_for_py\dll_for_py\main_task.cpp(105,18): error C2065: f: необъявленный идентификатор
C:\work\cpp_python\git\nm_lab_1\dll_for_py\dll_for_py\main_task.cpp(107,14): error C2065: f: необъявленный идентификатор
C:\work\cpp_python\git\nm_lab_1\dll_for_py\dll_for_py\main_task.cpp(108,14): error C2065: f: необъявленный идентификатор
C:\work\cpp_python\git\nm_lab_1\dll_for_py\dll_for_py\main_task.cpp(130,34): error C3861: pow: идентификатор не найден
C:\work\cpp_python\git\nm_lab_1\dll_for_py\dll_for_py\main_task.cpp(130,12): error C3861: fabs: идентификатор не найден
C:\work\cpp_python\git\nm_lab_1\dll_for_py\dll_for_py\main_task.cpp(147,33): error C3861: pow: идентификатор не найден
C:\work\cpp_python\git\nm_lab_1\dll_for_py\dll_for_py\main_task.cpp(162,18): error C3861: pow: идентификатор не найден
C:\work\cpp_python\git\nm_lab_1\dll_for_py\dll_for_py\main_task.cpp(167,3): error C2065: d_v: необъявленный идентификатор
C:\work\cpp_python\git\nm_lab_1\dll_for_py\dll_for_py\main_task.cpp(168,3): error C2065: d_v: необъявленный идентификатор
C:\work\cpp_python\git\nm_lab_1\dll_for_py\dll_for_py\main_task.cpp(169,3): error C2065: d_v: необъявленный идентификатор
C:\work\cpp_python\git\nm_lab_1\dll_for_py\dll_for_py\main_task.cpp(170,3): error C2065: d_v: необъявленный идентификатор
C:\work\cpp_python\git\nm_lab_1\dll_for_py\dll_for_py\main_task.cpp(171,3): error C2065: d_v: необъявленный идентификатор
C:\work\cpp_python\git\nm_lab_1\dll_for_py\dll_for_py\main_task.cpp(172,3): error C2065: d_v: необъявленный идентификатор
C:\work\cpp_python\git\nm_lab_1\dll_for_py\dll_for_py\main_task.cpp(173,3): error C2065: d_v: необъявленный идентификатор
  m_RK3_1.cpp
C:\work\cpp_python\git\nm_lab_1\dll_for_py\dll_for_py\m_RK3_1.cpp(245,23): warning C4267: инициализация: преобразование из "size_t" в "int"; возможна потеря данных
C:\work\cpp_python\git\nm_lab_1\dll_for_py\dll_for_py\m_RK3_1.cpp(248,2): error C3861: record: идентификатор не найден
